Workbook
Name 業務リスト: #REF!
Name 新宿: #REF!
Name 新宿: #REF!
Name 相続人リスト: #REF!,#REF!,#REF!,#REF!,#REF!,#REF!
Name 相続人リスト: #REF!,#REF!,#REF!,#REF!,#REF!,#REF!
Name 続柄リスト: #REF!
Name 続柄リスト: #REF!
Name 大坂: #REF!
Name 大坂: #REF!
Name 担当: 基本情報入力!$J$47:$K$164
Name 担当者リスト: #REF!
Name 担当者リスト: #REF!
Name 担当者情報: #REF!
Name 担当者情報: #REF!
Name 本店: #REF!
Name 本店: #REF!

Sheet 解約情報入力
A1: 解約情報入力
A3: 操作方法
A4: ① 【基本情報入力】シートに最新データを上書きしてください。（『初回送付セット基本データ』、または『戸籍申請書』のExcelからコピペ。住所等が最新情報になっているか要確認）
A5: ② 【基本情報入力(金融機関)】シートを最新データに更新してください。（『初回送付セット基本データ』からコピペのうえ、金融機関数増減をkintoneより反映させる）
A6: ③ 【解約情報入力】シートの（セルA15~D16）［発送日］と［宛先］を入力してください。
A7: ④ 送付書類⑴~⑻（セルE16~J23）の［内容］［送付通数］［返送の有無］［返送通数］を、メモを参考に入力してください。
A8: ⑤ 返送書類①~④（セルE24~J27）の［内容］［返送通数］を入力してください。
A9: ⑥ 証券口座がある場合、証券口座1~15（セルA30~D44）で証券会社名を選択してください。
A10: ⑦ 必要な書類を必要な通数印刷してください。
A11: ※【送付状・返送書類リスト】シートは両面(長辺綴じ)。送付状はPDF保存推奨。（あとから何を送ったから確認できるよう）
A12: ※【証券口座】シートは証券会社数によって印刷範囲を修正
A13: ※【送付先宛名シール】シートは代表相続人以外へ個別に送付する際に使用。当該シート内K列で送付先を指定し、手差し印刷
A15: 発送日 | B15: 45574 | G15: 内容 | H15: 送付通数 | I15: 返送の有無 | J15: 返送通数
A16: 宛先 | B16: 相続人①(代表) | E16: 送付書類 | F16: ⑴ | G16: 委任状 | H16: 4 | I16: 〇 | J16: 4
E17: 送付書類 | F17: ⑵ | G17: 解約金入金先口座番号記入用紙 | H17: 1 | I17: 〇 | J17: 1
E18: 送付書類 | F18: ⑶ | G18: 証券移管先口座番号記入用紙 | H18: 1 | I18: 〇 | J18: 1
A19: 宛先 | B19: =B16&"" -> 相続人①(代表) | E19: 送付書類 | F19: ⑷ | G19: 証券移管先口座番号記入用紙（特別口座用） | H19: 1 | I19: 〇 | J19: 1
A20: 続柄 | B20: =VLOOKUP($B$16,基本情報入力!$A$23:$J$35,2,FALSE)&"" | E20: 送付書類 | F20: ⑸ | G20: 返信用封筒 | H20: 1
A21: 氏名 | B21: =VLOOKUP($B$16,基本情報入力!$A$23:$J$35,3,FALSE)&"" | E21: 送付書類 | F21: ⑹ | G21: 遺産分割協議成立後のスケジュール | H21: 1
A22: ふりがな | B22: =VLOOKUP($B$16,基本情報入力!$A$23:$J$35,4,FALSE)&"" | E22: 送付書類 | F22: ⑺
A23: 生年月日 | B23: =VLOOKUP($B$16,基本情報入力!$A$23:$J$35,5,FALSE) -> 0 | E23: 送付書類 | F23: ⑻
A24: 〒 | B24: =VLOOKUP($B$16,基本情報入力!$A$23:$J$35,7,FALSE) -> 0 | E24: 送付書類 | F24: ⑼
A25: 住所1 | B25: =VLOOKUP($B$16,基本情報入力!$A$23:$J$35,8,FALSE)&"" | E25: 送付書類 | F25: ⑽
A26: 住所2 | B26: =VLOOKUP($B$16,基本情報入力!$A$23:$J$35,9,FALSE)&"" | E26: 返送書類① | G26: 印鑑証明書（原本） | J26: 4
A27: TEL | B27: =VLOOKUP($B$16,基本情報入力!$A$23:$J$35,10,FALSE)&"" | E27: 返送書類②
E28: 返送書類③
A30: 証券口座1
A31: 証券口座2
A32: 証券口座3
A33: 証券口座4
A34: 証券口座5
A35: 証券口座6
A36: 証券口座7
A37: 証券口座8
A38: 証券口座9
A39: 証券口座10
A40: 証券口座11
A41: 証券口座12
... A44: 証券口座15

Sheet 基本情報入力
A1: 基本情報入力
A2: ・こちらの『基本情報入力』シートの【⒈基本情報】~【⒋被相続人・相続人 基本情報】に必要事項を入力ください
A3: ・ヒアリングシートを参考に【⒍金融機関 基本情報】と【⒎不動産 基本情報】に必要事項を入力ください
A4: ・戸籍担当へ戸籍収集等を依頼される場合、『戸籍収集引継書』の14行より下、指示部分は直接入力ください
A5: ・『送付状』『返送書類リスト』は印刷後、分けずにホチキス止めして、まとめて送付ください
A8: ⒈基本情報 | B8: ※黄色セルは必ず入力ください | F8: ⒉送付書類 | H8: 返送書類リスト記載チェック | J8: ⒊返送書類
A9: 顧客コード | C9: 登記担当 | F9: ⑴ | G9: 契約書 | I9: TRUE | J9: 印鑑証明書（原本）
A10: 顧客名 | C10: 税チェ関与 | F10: ⑵ | G10: 重要事項説明書 | I10: TRUE
A11: プラン | C11: 値引きの有無 | F11: ⑶ | G11: 相続手続き業務に関する確認事項 | I11: TRUE
A12: 拠点 | C12: 委任状の日付 | F12: ⑷ | G12: 委任状 | I12: TRUE
A13: 担当① | C13: 担当② | F13: ⑸ | G13: 口座の凍結についての確認書 | I13: TRUE
A14: 初回送付日 | F14: ⑹ | G14: 不動産・金融機関情報一覧 | I14: TRUE
A15: 送付先1 | F15: ⑺ | G15: 戸籍関係情報 | I15: TRUE
A16: 送付先2 | F16: ⑻ | G16: 請求書 | I16: FALSE
A17: 委任状通数 | F17: ⑼ | G17: 返信用封筒(書類の返送にご使用ください) | I17: FALSE
A18: 印鑑証明書数 | F18: ⑽ | I18: FALSE
A19: 返信用封筒通数 | F19: ⑾ | I19: FALSE
A21: ⒋被相続人・相続人 基本情報
A22: 番号 | B22: 続柄 | C22: 氏名 (行政 太郎) | D22: ふりがな (ぎょうせい たろう) | E22: 生年月日 (R1.1.1) | F22: 死亡日 (R1.1.1) | G22: 〒 (000-0000) | H22: 住所1 (東京都中央区八重洲一丁目7-20) | I22: 住所2 (八重洲口会館2階) | J22: TEL (00-0000-0000) | K22: 本籍地 (東京都中央区八重洲一丁目7番20号) | L22: 筆頭者 (行政 太郎) | Q22: =IF(R22="",FALSE,TRUE) -> TRUE | R22: =J9&"" -> 印鑑証明書（原本）
A23: 被相続人 | B23: 本人 | Q23: =IF(R23="",FALSE,TRUE) -> FALSE | R23: =J10&""
A24: 相続人①(代表) | Q24: =IF(R24="",FALSE,TRUE) -> FALSE | R24: =J11&""
A25: 相続人② | Q25: =IF(R25="",FALSE,TRUE) -> FALSE | R25: =J12&""
A26: 相続人③ | Q26: =IF(R26="",FALSE,TRUE) -> FALSE | R26: =J13&""
A27: 相続人④
A28: 相続人⑤
A29: 相続人⑥
A30: 相続人⑦
A31: 相続人⑧
A32: 相続人⑨
A33: 相続人⑩
A34: 相続人⑪
A35: 相続人⑫
A37: ⒌戸籍担当
A38: 法定相続情報 | D38: 戸籍
A39: 配偶者 | D39: 対象者
A40: 相続人
A41: 相続人 | D41: 戸籍担当者
A42: 相続人 | D42: 拠点 | E42: 担当者
A43: 相続人 | D43: 東京 | E43: 増田
A46: ⒍金融機関 基本情報 | G46: ⒍不動産 基本情報
...

Sheet 送付状・返送書類リスト
C2: 書類送付のご案内
H3: =解約情報入力!B15 -> 45574
C5: =解約情報入力!B21&" 様" -> 様
C8: 拝啓 平素は格別のご高配を賜り厚く御礼申し上げます。 | J8: ="担当："&基本情報入力!$B$13 -> 担当：
C9: さて、本日下記の資料をお届け申し上げましたので、 | J9: =VLOOKUP(基本情報入力!$B$12,基本情報入力!$N$71:$S$1003,2,FALSE) -> #N/A
C10: 御査収いただきますようお願い申し上げます。敬具 | J10: =VLOOKUP(基本情報入力!$B$12,基本情報入力!$N$71:$S$1003,3,FALSE) -> #N/A
J11: =VLOOKUP(基本情報入力!$B$12,基本情報入力!$N$71:$S$1003,4,FALSE) -> #N/A
J12: ="TEL："&VLOOKUP(基本情報入力!$B$13,基本情報入力!$G$71:$H$1003,2,FALSE) -> #N/A
J13: ="FAX："&VLOOKUP(基本情報入力!$B$12,基本情報入力!$N$71:$S$1003,6,FALSE) -> #N/A
C15: 記
C17: 摘要 | I17: 通数
B18: =$D18&"" -> 委任状 | C18: =IF($D18="","",基本情報入力!$F9) -> ⑴ | D18: =IF(解約情報入力!$G16="","",解約情報入力!$G16)&IFERROR(VLOOKUP(解約情報入力!$G16,プルダウン!$B$4:$C$29,2,FALSE),"")&"" -> 委任状 | I18: =解約情報入力!H16&"" -> 4 | J18: =IF($I18="","","通") -> 通
B19: =$D19&"" -> 解約金入金先口座番号記入用紙 | C19: =IF($D19="","",基本情報入力!$F10) -> ⑵ | D19: =IF(解約情報入力!$G17="","",解約情報入力!$G17)&IFERROR(VLOOKUP(解約情報入力!$G17,プルダウン!$B$4:$C$29,2,FALSE),"")&"" -> 解約金入金先口座番号記入用紙 | I19: =解約情報入力!H17&"" -> 1 | J19: =IF($I19="","","通") -> 通
B20: =$D20&"" -> 証券移管先口座番号記入用紙 | C20: =IF($D20="","",基本情報入力!$F11) -> ⑶ | D20: =IF(解約情報入力!$G18="","",解約情報入力!$G18)&IFERROR(VLOOKUP(解約情報入力!$G18,プルダウン!$B$4:$C$29,2,FALSE),"")&"" -> 証券移管先口座番号記入用紙 | I20: =解約情報入力!H18&"" -> 1 | J20: =IF($I20="","","通") -> 通
B21: =$D21&"" -> 証券移管先口座番号記入用紙（特別口座用） | C21: =IF($D21="","",基本情報入力!$F12) -> ⑷ | D21: =IF(解約情報入力!$G19="","",解約情報入力!$G19)&IFERROR(VLOOKUP(解約情報入力!$G19,プルダウン!$B$4:$C$29,2,FALSE),"")&"" -> 証券移管先口座番号記入用紙（特別口座用） | I21: =解約情報入力!H19&"" -> 1 | J21: =IF($I21="","","通") -> 通
B22: =$D22&"" -> 返信用封筒 ※書類返送にご使用ください | C22: =IF($D22="","",基本情報入力!$F13) -> ⑸ | D22: =IF(解約情報入力!$G20="","",解約情報入力!$G20)&IFERROR(VLOOKUP(解約情報入力!$G20,プルダウン!$B$4:$C$29,2,FALSE),"")&"" -> 返信用封筒 ※書類返送にご使用ください | I22: =解約情報入力!H20&"" -> 1 | J22: =IF($I22="","","通") -> 通
B23: =$D23&"" -> 遺産分割協議成立後のスケジュール | C23: =IF($D23="","",基本情報入力!$F14) -> ⑹ | D23: =IF(解約情報入力!$G21="","",解約情報入力!$G21)&IFERROR(VLOOKUP(解約情報入力!$G21,プルダウン!$B$4:$C$29,2,FALSE),"")&"" -> 遺産分割協議成立後のスケジュール | I23: =解約情報入力!H21&"" -> 1 | J23: =IF($I23="","","通") -> 通
B24: =$D24&"" | C24: =IF($D24="","",基本情報入力!$F15) | D24: =IF(解約情報入力!$G22="","",解約情報入力!$G22)&IFERROR(VLOOKUP(解約情報入力!$G22,プルダウン!$B$4:$C$29,2,FALSE),"")&"" | I24: =解約情報入力!H22&"" | J24: =IF($I24="","","通")
B25: =$D25&"" | C25: =IF($D25="","",基本情報入力!$F16) | D25: =IF(解約情報入力!$G23="","",解約情報入力!$G23)&IFERROR(VLOOKUP(解約情報入力!$G23,プルダウン!$B$4:$C$29,2,FALSE),"")&"" | I25: =解約情報入力!H23&"" | J25: =IF($I25="","","通")
B26: =$D26&"" | C26: =IF($D26="","",基本情報入力!$F17) | D26: =IF(解約情報入力!$G24="","",解約情報入力!$G24)&IFERROR(VLOOKUP(解約情報入力!$G24,プルダウン!$B$4:$C$29,2,FALSE),"")&"" | I26: =解約情報入力!H24&"" | J26: =IF($I26="","","通")
B27: =$D27&"" | C27: =IF($D27="","",基本情報入力!$F18) | D27: =IF(解約情報入力!$G25="","",解約情報入力!$G25)&IFERROR(VLOOKUP(解約情報入力!$G25,プルダウン!$B$4:$C$29,2,FALSE),"")&"" | I27: =解約情報入力!H25&"" | J27: =IF($I27="","","通")
C28: 通信欄：
C29: 平素よりお世話になっております。 上記書類をお送りいたしますので、お手数ではございますが、送付状裏面(返送書類リスト)をご確認いただき、ご対応の上ご返送くださいますようお願い申し上げます。 ご不明点等ございましたら、お気軽にご連絡ください。 業務完了まで、何卒よろしくお願い致します。
C32: 返送書類リスト | G32: =C5 -> 様
C34: 以下、⒈⒉のリストに記載のあるものを、同封の返信用封筒にへ弊社へご返送願います
C35: ⒈ 弊社からお送りした書類のうち、ご返送いただきたい書類
C36: ☑ | E36: № | F36: 名称 | G36: 詳細 | I36: 返送 通数
C37: =IF($I37="","","□") -> □ | E37: {=_xlfn._xlws.FILTER(解約情報入力!$F$16:$G$25,解約情報入力!$I$16:$I$25<>"")} -> ⑴ | F37: 委任状 | G37: =IFERROR(VLOOKUP($F37,プルダウン!$B$4:$D$29,3,FALSE),"")&"" -> ご署名ご捺印（実印）のうえ、ご返送願います。 | I37: =IFERROR(VLOOKUP($F37,解約情報入力!$G$16:$J$25,4,FALSE),"")&"" -> 4 | J37: =IF($I37="","","通") -> 通
C38: =IF($I38="","","□") -> □ | E38: ⑵ | F38: 解約金入金先口座番号記入用紙 | G38: =IFERROR(VLOOKUP($F38,プルダウン!$B$4:$D$29,3,FALSE),"")&"" -> 内容をご確認のうえ、被相続人様の預貯金の解約金送金先に指定される口座の情報をご記入願います。 | I38: =IFERROR(VLOOKUP($F38,解約情報入力!$G$16:$J$25,4,FALSE),"")&"" -> 1 | J38: =IF($I38="","","通") -> 通
C39: =IF($I39="","","□") -> □ | E39: ⑶ | F39: 証券移管先口座番号記入用紙 | G39: =IFERROR(VLOOKUP($F39,プルダウン!$B$4:$D$29,3,FALSE),"")&"" -> 内容をご確認のうえ、被相続人様の有価証券の移管先に指定される証券口座の情報をご記入願います。 | I39: =IFERROR(VLOOKUP($F39,解約情報入力!$G$16:$J$25,4,FALSE),"")&"" -> 1 | J39: =IF($I39="","","通") -> 通
C40: =IF($I40="","","□") -> □ | E40: ⑷ | F40: 証券移管先口座番号記入用紙（特別口座用） | G40: =IFERROR(VLOOKUP($F40,プルダウン!$B$4:$D$29,3,FALSE),"")&"" -> 内容をご確認のうえ、被相続人様の有価証券の移管先に指定される証券口座の情報と、21桁の加入者口座コードをご記入願います。 | I40: =IFERROR(VLOOKUP($F40,解約情報入力!$G$16:$J$25,4,FALSE),"")&"" -> 1 | J40: =IF($I40="","","通") -> 通
C41: =IF($I41="","","□") | G41: =IFERROR(VLOOKUP($F41,プルダウン!$B$4:$D$29,3,FALSE),"")&"" | I41: =IFERROR(VLOOKUP($F41,解約情報入力!$G$16:$J$25,4,FALSE),"")&"" | J41: =IF($I41="","","通")
C42: =IF($I42="","","□") | G42: =IFERROR(VLOOKUP($F42,プルダウン!$B$4:$D$29,3,FALSE),"")&"" | I42: =IFERROR(VLOOKUP($F42,解約情報入力!$G$16:$J$25,4,FALSE),"")&"" | J42: =IF($I42="","","通")
C43: =IF($I43="","","□") | G43: =IFERROR(VLOOKUP($F43,プルダウン!$B$4:$D$29,3,FALSE),"")&"" | I43: =IFERROR(VLOOKUP($F43,解約情報入力!$G$16:$J$25,4,FALSE),"")&"" | J43: =IF($I43="","","通")
C44: =IF($I44="","","□") | G44: =IFERROR(VLOOKUP($F44,プルダウン!$B$4:$D$29,3,FALSE),"")&"" | I44: =IFERROR(VLOOKUP($F44,解約情報入力!$G$16:$J$25,4,FALSE),"")&"" | J44: =IF($I44="","","通")
C45: =IF($I45="","","□") | G45: =IFERROR(VLOOKUP($F45,プルダウン!$B$4:$D$29,3,FALSE),"")&"" | I45: =IFERROR(VLOOKUP($F45,解約情報入力!$G$16:$J$25,4,FALSE),"")&"" | J45: =IF($I45="","","通")
C46: =IF($I46="","","□") | G46: =IFERROR(VLOOKUP($F46,プルダウン!$B$4:$D$29,3,FALSE),"")&"" | I46: =IFERROR(VLOOKUP($F46,解約情報入力!$G$16:$J$25,4,FALSE),"")&"" | J46: =IF($I46="","","通")
C47: ⒉ ご準備のうえ、ご返送いただきたい書類
C48: ☑ | E48: 名称 | G48: 詳細 | I48: 返送 通数
C49: =IF($E49="","","□") -> □ | E49: =解約情報入力!G26&"" -> 印鑑証明書（原本） | G49: =IFERROR(IF(E49="印鑑証明書（原本）",$C$5&"分の"&(VLOOKUP($E49,プルダウン!$E$4:$F$29,2,FALSE)),VLOOKUP($E49,プルダウン!$E$4:$F$29,2,FALSE)),"")&"" -> 様分の約1ヵ月以内に発行した印鑑証明書を右記通数ご返送願います。※マイナンバーカードがあれば、コンビニ取得可能です | I49: =解約情報入力!J26&"" -> 4 | J49: {=_xlfn.IFS($I49="","",$G49="すべて","",TRUE,"通")} -> 通
...

Sheet 委任状
J1: =IFERROR(VLOOKUP($D$2,送付状・返送書類リスト!$B$18:$C$27,2,FALSE),"") -> ⑴
D2: 委任状
A4: 主たる事務所所在 | E4: =基本情報入力!$P72&"" -> 東京都中央区八重洲1-7-20 | I4: =基本情報入力!$R72&"" -> 03-6868-8328
A5: 従たる事務所所在 | E5: =基本情報入力!$P73&"" -> 東京都新宿区西新宿2-7-1 | I5: =基本情報入力!$R73&"" -> 03-6868-8941
E6: =基本情報入力!$P74&"" -> 神奈川県横浜市神奈川区鶴屋町2-12-5 | I6: =基本情報入力!$R74&"" -> 045-550-4249
E7: =基本情報入力!$P75&"" -> 愛知県名古屋市中区栄3-2-3 | I7: =基本情報入力!$R75&"" -> 052-766-5024
E8: =基本情報入力!$P76&"" -> 大阪府大阪市北区中之島2-2-2 | I8: =基本情報入力!$R76&"" -> 06-7878-4155
A10: 名称 | D10: 行政書士法人チェスター
A11: 代表社員 | D11: =基本情報入力!I72 -> 清水茜作
A12: 行政書士 | D12: =_xlfn.CONCAT(基本情報入力!$J$72:$J$187) -> 伊原慶 浅倉貴行 西田竜介 藤本義昌 石川綾子 吉田幸寛 金井佑介 布施祐太郎 栗原大輔 石井祐貴 柴田彩香 松本拓弥 森町翼 鳥山剛史 中島絵里 小島文子 福岡なつみ
A14: 補助者 | D14: =_xlfn.CONCAT(基本情報入力!$K$72:$K$187) -> 池田絢音 増田千尋 川原千里 山崎宇紗子 君島絵梨 青柳由里子 山口知代 増田波輝 佐竹彩 佐野雅絵 宮城明香 丸山慧子 森中絵梨佳 東三条佑圭梨 小森和正 米田由香 菊川智恵子 宇野綾華 南香南江 土田修平 星野里紗 亀岡菜摘 白金大翔 三宅真莉奈 梅田奈央 芦田昭子 安西伽奈美 宮持玲那 進藤莉花 司馬里美 辻充代 植田愛望
A17: 上記の者を 遺産整理受任者 に選任し、被相続人 | G17: =基本情報入力!$C$23&"" | H17: の相続財産の承継に関して必要な
A18: 下記事務他一切の事務を処理する権限を委任します。
A20: 委任事項の内容
A21: ① | B21: 被相続人作成の遺言の有無の調査、遺言公正証書の謄本の請求及び受領に関する一切の件
A22: ② | B22: 官公署に対する諸手続、その他戸籍・除籍・原戸籍・戸籍の附票（本籍・筆頭者記載）、住民票（本籍・筆頭者・世帯主・続柄記載）、固定資産税評価証明書・固定資産名寄台帳の写し・農地基本台帳等（単有及び共有する全ての物件について）の申請並びに受領に関する一切の件
A25: ③ | B25: 今般相続手続に必要となる、遺産分割協議書、申請書、財産目録、遺産配分に関する説明書、その他一切の書類作成
A27: ④ | B27: 金融機関、ゆうちょ銀行、証券会社、保険会社、かんぽ生命その他法人等に対する、現存照会または取引履歴・入出金照会、残高証明の請求及び受領、各種書類または証書類の提出および受領、預貯金の解約、被相続人が行っていた契約（契約に類する約定を含む）の承継・変更・解約、貸金庫取引の解約並びに保管物の代表相続人への引渡、株式・有価証券等寄託物件の返還または相続移管並びに受渡、払戻金・満期金・株式配当金・出資金・保険金・還付金・給付金・売却代金等の請求、連絡、照会、その他預貯金・生命保険・株式・有価証券類の一切の相続手続
A32: ⑤ | B32: 相続人が行なうべき前各号の事務について必要な調査ならびに助言
A33: ⑥ | B33: その他、相続財産の承継のため必要な一切の事務
A34: ⑦ | B34: 上記被相続人の法定相続情報一覧図の作成、保管、交付再交付の申し出及び受領に関する一切の件 尚、上記法定相続情報の利用目的は、登記申請及び預金払戻手続きであり、必要な写しの通数は10通
A36: ⑧ | B36: 証券保管振替機構に対する、上記被相続人及び私の登録済加入者情報に関する開示請求及びその情報を記載した「登録済加入者情報通知書」の受領等に係る一切の件
A38: ⑨ | B38: 前各号の事務処理を行うために必要とされる復代理人選任に関する一切の件
A39: ⑩ | B39: 本状及び添付書類の還付請求並びにその受領に関する一切の件
A41: 令和 年 月 日
A43: 住所 | D43: =VLOOKUP(解約情報入力!$B$16,基本情報入力!$A$23:$J$35,8,FALSE)&""
D44: =VLOOKUP(解約情報入力!$B$16,基本情報入力!$A$23:$J$35,9,FALSE)&""
A45: 氏名
D47: =VLOOKUP(解約情報入力!$B$16,基本情報入力!$A$23:$J$35,3,FALSE)&" 様" -> 様

Sheet 銀行口座
B1: 解約金入金先口座番号記入用紙 | F1: =IFERROR(VLOOKUP($B$1,送付状・返送書類リスト!$B$18:$C$27,2,FALSE),"") -> ⑵
B3: 預貯金解約に伴う入金先口座情報をご記入ください。
B5: ◆ゆうちょ銀行
B6: ※解約口座にゆうちょ銀行がある場合には必ずご記入ください。
B7: ※ゆうちょ銀行の解約金は代表相続人のゆうちょ銀行口座にのみ送金可能です。口座を保有していない場合 には、お手数ではございますが、新規開設くださいますようお願いいたします。
B8: フリガナ
B9: 口座名義 （金融機関登録の氏名） | D9: ※相続人ご本人様に限る
B10: 記号－番号 | D10: ―
B11: 店名 （例：〇二八） | D11: ※通帳見開きページの下方に記載
B12: 店番 （例：028） | D12: ※通帳見開きページの下方に記載
B13: 預金種目 | D13: 普通 ・ 貯蓄
B14: 口座番号 | D14: ※通帳見開きページの下方に記載
D15: ※振込手数料がかかる場合は残高より差し引かれますこと、予めご了承ください。
B17: ◆その他の銀行、信用金庫等
B18: ※すべての預貯金について、上記のゆうちょ銀行への送金を希望される場合は右の□に✓を入れ、 下記は空欄のままご返送願います。 | E18: □
B19: フリガナ
B20: 口座名義 （金融機関登録の氏名） | D20: ※相続人ご本人様に限る
B21: 銀行名
B22: 支店名
B23: 支店コード
B24: 科目 | D24: 普通 ・ 貯蓄 ・ 当座
B25: 口座番号
D26: ※振込手数料がかかる場合は残高より差し引かれますこと、予めご了承ください。

Sheet 証券口座
B1: 証券移管先口座番号記入用紙 | F1: =IFERROR(VLOOKUP($B$1,送付状・返送書類リスト!$B$18:$C$27,2,FALSE),"") -> ⑶
B3: 有価証券の移管にともなう移管先口座情報をご記入ください
B5: ① | C5: =解約情報入力!B30&""
B7: フリガナ
B8: 口座名義 （金融機関登録の氏名） | D8: ※相続人ご本人様に限る
B9: 支店名
B10: 支店コード
B11: 口座番号
B14: ② | C14: =解約情報入力!B31&""
B16: フリガナ
B17: 口座名義 （金融機関登録の氏名） | D17: ※相続人ご本人様に限る
B18: 支店名
B19: 支店コード
B20: 口座番号
B23: ③ | C23: =解約情報入力!B32&""
B25: フリガナ
B26: 口座名義 （金融機関登録の氏名） | D26: ※相続人ご本人様に限る
B27: 支店名
B28: 支店コード
B29: 口座番号
B32: ④ | C32: =解約情報入力!B33&""
B34: フリガナ
B35: 口座名義 （金融機関登録の氏名） | D35: ※相続人ご本人様に限る
B36: 支店名
B37: 支店コード
B38: 口座番号
B41: ⑤ | C41: =解約情報入力!B34&""
B43: フリガナ
B44: 口座名義 （金融機関登録の氏名） | D44: ※相続人ご本人様に限る
B45: 支店名
B46: 支店コード
B47: 口座番号
B50: ⑥ | C50: =解約情報入力!B35&""
B52: フリガナ
B53: 口座名義 （金融機関登録の氏名） | D53: ※相続人ご本人様に限る
B54: 支店名
B55: 支店コード
B56: 口座番号
B59: ⑦ | C59: =解約情報入力!B36&""
B61: フリガナ
...

Sheet 銀行口座 (ゆうちょが他行OKになったら)
B1: 解約金入金先口座番号記入用紙 | F1: =IFERROR(VLOOKUP($B$1,送付状・返送書類リスト!$B$18:$C$27,2,FALSE),"") -> ⑵
B3: 預貯金解約に伴う入金先口座情報をご記入ください。
B5: ◆ゆうちょ銀行を指定される場合
B6: ※ゆうちょ銀行を他行解約金の送金先に指定する場合は、『記号-番号（例：12345-6789123）』のほか、通帳見 開き下部記載の『支店名（例：〇二八店）』や『口座番号（例：1234567）』等も必要です。お手数ですが、下 記項目全てご記入願います。
B8: フリガナ
B9: 口座名義 （金融機関登録の氏名） | D9: ※相続人ご本人様に限る
B10: 記号－番号 （例：12345-6789123） | D10: ―
B11: 店名 （例：〇二八） | D11: ※通帳見開きページの下方に記載
B12: 店番 （例：028） | D12: ※通帳見開きページの下方に記載
B13: 預金種目 | D13: 普通 ・ 貯蓄
B14: 口座番号 （例：1234567） | D14: ※通帳見開きページの下方に記載
D15: ※振込手数料がかかる場合は残高より差し引かれますこと、予めご了承ください。
B17: ◆ゆうちょ銀行以外を指定される場合
B18: フリガナ
B19: 口座名義 （金融機関登録の氏名） | D19: ※相続人ご本人様に限る
B20: 銀行名
B21: 支店名
B22: 支店コード
B23: 科目 | D23: 普通 ・ 貯蓄 ・ 当座
B24: 口座番号
D25: ※振込手数料がかかる場合は残高より差し引かれますこと、予めご了承ください。

Sheet 証券代行部
B1: 証券移管先口座番号記入用紙（特別口座用） | Y1: =IFERROR(VLOOKUP($B$1,送付状・返送書類リスト!$B$18:$C$27,2,FALSE),"") -> ⑷
B3: 証券会社を通さず所有されていた上場株式の移管にともなう移管先口座情報をご記入ください
B6: フリガナ
B7: 口座名義 （金融機関登録の氏名） | D7: ※相続人ご本人様に限る
B8: 証券会社名
B9: 支店名
B10: 支店コード
B11: 口座番号
B12: 加入者口座コード （21桁）
B16: ◆証券代行部にある未受領配当金の入金先口座番号
B18: フリガナ
B19: 口座名義 （金融機関登録の氏名） | D19: ※相続人ご本人様に限る
B20: 銀行名
B21: 支店名
B22: 支店コード
B23: 科目 | D23: 普通 ・ 貯蓄 ・ 当座
B24: 口座番号
D25: ※振込手数料がかかる場合は残高より差し引かれますこと、予めご了承ください。

Sheet 協議後のスケジュール
B1: 【遺産分割協議成立後のスケジュール】 | F1: =IFERROR(VLOOKUP("遺産分割協議成立後のスケジュール",送付状・返送書類リスト!$B$18:$C$27,2,FALSE),"") -> ⑹
A2: 行政書士法人チェスターのお手続きが終了次第、司法書士法人チェスターへ引き継ぎます。
C4: 業務内容 | E4: 必要期間
B5: ① | C5: 預貯金口座の解約 | E5: ※１～２ヶ月
B6: ② | C6: 相続人様名義の証券口座への移管サポート
B7: ③ | C7: 相続登記（不動産の名義変更） | E7: ※ 1～1.5ヶ月
B8: ※金融機関数・不動産数等により異なりますので、あくまで目安となります。
B10: 【留意事項】
B11: ・行政書士法人チェスターにて金融機関の解約・移管のお手続きを行います（1～2ヶ月）
B13: ・全ての金融機関への解約・移管の申請後、必要資料を司法書士法人チェスターに引き継ぎ、司 法書士法人チェスターより御連絡差し上げます。登記実行時に、登録免許税を含めた登記手続 き費用を司法書士法人チェスターよりご請求させて頂きます。（1～1.5ヶ月）
B17: ・全ての金融機関より、解約・移管手続きの完了通知を取得しましたら、御報告致します。行政書 士法人チェスターにて取得しました資料一式をご返却させて頂きますと共に、実費精算分と行政書 士の残報酬をご請求させて頂きます。
F21: 以上

Sheet 送付先宛名シール（個別）
M2: ① | O2: ② | P2: 〒000-0000
B3: =IF($M3="〒0","",$M3) | G3: =$B3 | K3: 相続人①(代表) | M3: {=IFERROR("〒"&(_xlfn.IFS(K3="",VLOOKUP(基本情報入力!$B$12,基本情報入力!$N$71:$S$138,2,FALSE),K3<>"",VLOOKUP(K3,基本情報入力!$A$23:$K$35,7,FALSE))),"")} -> 〒0 | P3: 東京都港区虎ノ門 0-0-0
P4: □□ビル 12F
B5: =IF($M5="","",$M5) | G5: =$B5 | M5: {=IFERROR(_xlfn.IFS(K3="",VLOOKUP(基本情報入力!$B$12,基本情報入力!$N$71:$S$138,3,FALSE),K3<>"",VLOOKUP(K3,基本情報入力!$A$23:$K$35,8,FALSE)&""),"")} | P5: ピー + エスシー株式会社
B6: =IF($M6="","",$M6) | G6: =$B6 | M6: {=_xlfn.IFS(K3="",VLOOKUP(基本情報入力!$B$12,基本情報入力!$N$71:$S$138,4,FALSE),K3<>"",VLOOKUP(K3,基本情報入力!$A$23:$K$35,9,FALSE)&"")} | P6: □□グループ
B7: =IF($M7="","",$M7) -> 様 | G7: =$B7 -> 様 | M7: {=IFERROR(_xlfn.IFS(K3="","行政書士法人チェスター",K3<>"",VLOOKUP(K3,基本情報入力!$A$23:$K$35,3,FALSE)&" 様"),"")} -> 様 | P7: 主任 高橋 直也 様
C9: =IF($M9="TEL：","",$M9) | H9: =$C9 | M9: =IFERROR("TEL："&(IF(K3="",VLOOKUP(基本情報入力!$B$13,基本情報入力!$G$71:$H$136,2,FALSE),VLOOKUP(K3,基本情報入力!$A$23:$K$35,10,FALSE))),"") -> TEL：
B13: =IF($M13="〒0","",$M13) | G13: =$B13 | K13: 相続人② | M13: {=IFERROR("〒"&(_xlfn.IFS(K13="",VLOOKUP(基本情報入力!$B$12,基本情報入力!$N$71:$S$138,2,FALSE),K13<>"",VLOOKUP(K13,基本情報入力!$A$23:$K$35,7,FALSE))),"")} -> 〒0 | N13: 編集する時の注意！ ・列の幅を変更したり、行を追加しないでください。 印刷する時の注意！ ・プリンターの印刷設定より、給紙トレイを「手差し」に、用紙種類を「ラベル・厚紙」などに変更し、必ず手差しトレイから給紙してください。 印刷の向きは、印刷面下、差し込み方向矢印と逆にセットしてください。 アレンジのポイント！ ・文字のフォント、色、背景を自由に変えられます。
B15: =IF($M15="","",$M15) | G15: =$B15 | M15: {=IFERROR(_xlfn.IFS(K13="",VLOOKUP(基本情報入力!$B$12,基本情報入力!$N$71:$S$138,3,FALSE),K13<>"",VLOOKUP(K13,基本情報入力!$A$23:$K$35,8,FALSE)&""),"")}
B16: =IF($M16="","",$M16) | G16: =$B16 | M16: {=_xlfn.IFS(K13="",VLOOKUP(基本情報入力!$B$12,基本情報入力!$N$71:$S$138,4,FALSE),K13<>"",VLOOKUP(K13,基本情報入力!$A$23:$K$35,9,FALSE)&"")}
B17: =IF($M17="","",$M17) -> 様 | G17: =$B17 -> 様 | M17: {=IFERROR(_xlfn.IFS(K13="","行政書士法人チェスター",K13<>"",VLOOKUP(K13,基本情報入力!$A$23:$K$35,3,FALSE)&" 様"),"")} -> 様
C19: =IF($M19="TEL：","",$M19) | H19: =$C19 | M19: =IFERROR("TEL："&(IF(K13="",VLOOKUP(基本情報入力!$B$13,基本情報入力!$G$71:$H$136,2,FALSE),VLOOKUP(K13,基本情報入力!$A$23:$K$35,10,FALSE))),"") -> TEL：
B23: =IF($M23="〒0","",$M23) | G23: =$B23 | K23: 相続人③ | M23: {=IFERROR("〒"&(_xlfn.IFS(K23="",VLOOKUP(基本情報入力!$B$12,基本情報入力!$N$71:$S$138,2,FALSE),K23<>"",VLOOKUP(K23,基本情報入力!$A$23:$K$35,7,FALSE))),"")} -> 〒0
B25: =IF($M25="","",$M25) | G25: =$B25 | M25: {=IFERROR(_xlfn.IFS(K23="",VLOOKUP(基本情報入力!$B$12,基本情報入力!$N$71:$S$138,3,FALSE),K23<>"",VLOOKUP(K23,基本情報入力!$A$23:$K$35,8,FALSE)&""),"")}
B26: =IF($M26="","",$M26) | G26: =$B26 | M26: {=_xlfn.IFS(K23="",VLOOKUP(基本情報入力!$B$12,基本情報入力!$N$71:$S$138,4,FALSE),K23<>"",VLOOKUP(K23,基本情報入力!$A$23:$K$35,9,FALSE)&"")}
B27: =IF($M27="","",$M27) -> 様 | G27: =$B27 -> 様 | M27: {=IFERROR(_xlfn.IFS(K23="","行政書士法人チェスター",K23<>"",VLOOKUP(K23,基本情報入力!$A$23:$K$35,3,FALSE)&" 様"),"")} -> 様
C29: =IF($M29="TEL：","",$M29) | H29: =$C29 | M29: =IFERROR("TEL："&(IF(K23="",VLOOKUP(基本情報入力!$B$13,基本情報入力!$G$71:$H$136,2,FALSE),VLOOKUP(K23,基本情報入力!$A$23:$K$35,10,FALSE))),"") -> TEL：
B33: =IF($M33="〒0","",$M33) | G33: =$B33 | M33: {=IFERROR("〒"&(_xlfn.IFS(K33="",VLOOKUP(基本情報入力!$B$12,基本情報入力!$N$71:$S$138,2,FALSE),K33<>"",VLOOKUP(K33,基本情報入力!$A$23:$K$35,7,FALSE))),"")}
B35: =IF($M35="","",$M35) | G35: =$B35 | M35: {=IFERROR(_xlfn.IFS(K33="",VLOOKUP(基本情報入力!$B$12,基本情報入力!$N$71:$S$138,3,FALSE),K33<>"",VLOOKUP(K33,基本情報入力!$A$23:$K$35,8,FALSE)&""),"")}
B36: =IF($M36="","",$M36) -> #N/A | G36: =$B36 -> #N/A | M36: {=_xlfn.IFS(K33="",VLOOKUP(基本情報入力!$B$12,基本情報入力!$N$71:$S$138,4,FALSE),K33<>"",VLOOKUP(K33,基本情報入力!$A$23:$K$35,9,FALSE)&"")} -> #N/A
B37: =IF($M37="","",$M37) -> 行政書士法人チェスター | G37: =$B37 -> 行政書士法人チェスター | M37: {=IFERROR(_xlfn.IFS(K33="","行政書士法人チェスター",K33<>"",VLOOKUP(K33,基本情報入力!$A$23:$K$35,3,FALSE)&" 様"),"")} -> 行政書士法人チェスター
C39: =IF($M39="TEL：","",$M39) | H39: =$C39 | M39: =IFERROR("TEL："&(IF(K33="",VLOOKUP(基本情報入力!$B$13,基本情報入力!$G$71:$H$136,2,FALSE),VLOOKUP(K33,基本情報入力!$A$23:$K$35,10,FALSE))),"")
B43: =IF($M43="〒0","",$M43) | G43: =$B43 | M43: {=IFERROR("〒"&(_xlfn.IFS(K43="",VLOOKUP(基本情報入力!$B$12,基本情報入力!$N$71:$S$138,2,FALSE),K43<>"",VLOOKUP(K43,基本情報入力!$A$23:$K$35,7,FALSE))),"")}
B45: =IF($M45="","",$M45) | G45: =$B45 | M45: {=IFERROR(_xlfn.IFS(K43="",VLOOKUP(基本情報入力!$B$12,基本情報入力!$N$71:$S$138,3,FALSE),K43<>"",VLOOKUP(K43,基本情報入力!$A$23:$K$35,8,FALSE)&""),"")}
B46: =IF($M46="","",$M46) -> #N/A | G46: =$B46 -> #N/A | M46: {=_xlfn.IFS(K43="",VLOOKUP(基本情報入力!$B$12,基本情報入力!$N$71:$S$138,4,FALSE),K43<>"",VLOOKUP(K43,基本情報入力!$A$23:$K$35,9,FALSE)&"")} -> #N/A
B47: =IF($M47="","",$M47) -> 行政書士法人チェスター | G47: =$B47 -> 行政書士法人チェスター | M47: {=IFERROR(_xlfn.IFS(K43="","行政書士法人チェスター",K43<>"",VLOOKUP(K43,基本情報入力!$A$23:$K$35,3,FALSE)&" 様"),"")} -> 行政書士法人チェスター
C49: =IF($M49="TEL：","",$M49) | H49: =$C49 | M49: =IFERROR("TEL："&(IF(K43="",VLOOKUP(基本情報入力!$B$13,基本情報入力!$G$71:$H$136,2,FALSE),VLOOKUP(K43,基本情報入力!$A$23:$K$35,10,FALSE))),"")
B53: =IF($M53="〒0","",$M53) | G53: =$B53 | M53: {=IFERROR("〒"&(_xlfn.IFS(K53="",VLOOKUP(基本情報入力!$B$12,基本情報入力!$N$71:$S$138,2,FALSE),K53<>"",VLOOKUP(K53,基本情報入力!$A$23:$K$35,7,FALSE))),"")}
B55: =IF($M55="","",$M55) | G55: =$B55 | M55: {=IFERROR(_xlfn.IFS(K53="",VLOOKUP(基本情報入力!$B$12,基本情報入力!$N$71:$S$138,3,FALSE),K53<>"",VLOOKUP(K53,基本情報入力!$A$23:$K$35,8,FALSE)&""),"")}
B56: =IF($M56="","",$M56) -> #N/A | G56: =$B56 -> #N/A | M56: {=_xlfn.IFS(K53="",VLOOKUP(基本情報入力!$B$12,基本情報入力!$N$71:$S$138,4,FALSE),K53<>"",VLOOKUP(K53,基本情報入力!$A$23:$K$35,9,FALSE)&"")} -> #N/A
B57: =IF($M57="","",$M57) -> 行政書士法人チェスター | G57: =$B57 -> 行政書士法人チェスター | M57: {=IFERROR(_xlfn.IFS(K53="","行政書士法人チェスター",K53<>"",VLOOKUP(K53,基本情報入力!$A$23:$K$35,3,FALSE)&" 様"),"")} -> 行政書士法人チェスター
C59: =IF($M59="TEL：","",$M59) | H59: =$C59 | M59: =IFERROR("TEL："&(IF(K53="",VLOOKUP(基本情報入力!$B$13,基本情報入力!$G$71:$H$136,2,FALSE),VLOOKUP(K53,基本情報入力!$A$23:$K$35,10,FALSE))),"")

Sheet プルダウン
A3: 〇✖ | B3: 送付書類名称 | C3: 送付書の注意書き | D3: 返送書類リストの文言 | E3: 返送書類名称 | F3: 返送書類リストの文言
A4: 〇 | B4: 委任状 | D4: ご署名ご捺印（実印）のうえ、ご返送願います。 | E4: 印鑑証明書（原本） | F4: 約1ヵ月以内に発行した印鑑証明書を右記通数ご返送願います。※マイナンバーカードがあれば、コンビニ取得可能です
B5: 解約金入金先口座番号記入用紙 | D5: 内容をご確認のうえ、被相続人様の預貯金の解約金送金先に指定される口座の情報をご記入願います。 | E5: 印鑑証明書 （原本） | F5: 約1ヵ月以内に発行した印鑑証明書を右記通数ご返送願います。
B6: 証券移管先口座番号記入用紙 | D6: 内容をご確認のうえ、被相続人様の有価証券の移管先に指定される証券口座の情報をご記入願います。
B7: 証券移管先口座番号記入用紙（特別口座用） | D7: 内容をご確認のうえ、被相続人様の有価証券の移管先に指定される証券口座の情報と、21桁の加入者口座コードをご記入願います。
B8: 返信用封筒 | C8: ※書類返送にご使用ください
B9: 遺産分割協議成立後のスケジュール
B10: 遺産分割協議書（単独署名用） | D10: ご署名ご捺印（実印）のうえ、ご返送願います。
B11: 遺産分割協議書（連署用） | D11: ご署名ご捺印（実印）のうえ、同封の返信用レターパックにて、次の相続人様へ送付願います。
B12: 返信用封筒（連署用） | C12: ※次の相続人様へ書類を送付する際にご使用ください
B13: （登記用）委任状 | D13: ご署名ご捺印（実印）のうえ、ご返送願います。
B14: （登記用）お手続きの流れ
B15: （登記用）登記識別情報 郵送先指示書 | D15: ご署名ご捺印（実印）と、登記識別情報（権利証）の送付先についてご記入のうえ、ご返送願います。
B16: 相続登記御見積書 | C16: ※司法書士による不動産名義変更の御見積書です
B17: 御見積書

Sheet 返送書類リスト(ひな型)
B1: 返送書類リスト | F1: =IFERROR(VLOOKUP($B$1,'送付状(法定)'!$B$18:$O$28,2,FALSE),"")
B5: 以下、⒈⒉のリストに記載のあるものを、同封の返信用封筒にへ弊社へご返送願います
B6: ⒈ 弊社からお送りした書類のうち、ご返送いただきたい書類
B7: ☑ | C7: № | D7: 名称 | E7: 詳細 | F7: 返送 通数
B17: ⒉ ご準備のうえ、ご返送いただきたい書類
B18: ☑ | C18: 名称 | E18: 詳細 | F18: 返送 通数

Sheet 送付状(法定)
C2: 書類送付のご案内
AA3: =IF($V$3="","⇐日付入力","") -> ⇐日付入力
C5: =IF(VLOOKUP(基本情報入力!$B$15,基本情報入力!$A$23:$K$35,3,FALSE)="","",VLOOKUP(基本情報入力!$B$15,基本情報入力!$A$23:$K$35,3,FALSE)) -> #N/A
K6: 様
T7: 行政書士法人チェスター
W8: 担当： | Y8: =基本情報入力!$B$13 -> 0
C9: 拝啓 平素は格別のご高配を賜り厚く御礼申し上げます。 | Z9: =VLOOKUP(基本情報入力!$B$12,基本情報入力!$N$47:$S$81,2,FALSE) -> #N/A
C10: さて、本日下記の資料をお届け申し上げましたので、 | Z10: =VLOOKUP(基本情報入力!$B$12,基本情報入力!$N$47:$S$81,3,FALSE) -> #N/A
C11: 御査収いただきますようお願い申し上げます。敬具 | Z11: =VLOOKUP(基本情報入力!$B$12,基本情報入力!$N$47:$S$81,4,FALSE) -> #N/A
V12: TEL: | W12: =VLOOKUP(基本情報入力!$B$13,基本情報入力!$G$48:$H$80,2,FALSE) -> #N/A
V13: FAX: | W13: =VLOOKUP(基本情報入力!$B$12,基本情報入力!$N$48:$S$81,6,FALSE) -> #N/A
C15: 記
C17: 摘要 | W17: 通数（部数）
B18: =$D18&"" -> 法定相続情報一覧図 | C18: =IF($D18="","",基本情報入力!$F9) -> ⑴ | D18: 法定相続情報一覧図 | Y18: =IF($X18="","","通")
B19: =$D19&"" | C19: =IF($D19="","",基本情報入力!$F10) | Y19: =IF($X19="","","通")
B20: =$D20&"" | C20: =IF($D20="","",基本情報入力!$F11) | Y20: =IF($X20="","","通")
B21: =$D21&"" | C21: =IF($D21="","",基本情報入力!$F12) | Y21: =IF($X21="","","通")
B22: =$D22&"" | C22: =IF($D22="","",基本情報入力!$F13) | Y22: =IF($X22="","","通")
B23: =$D23&"" | C23: =IF($D23="","",基本情報入力!$F14) | Y23: =IF($X23="","","通")
B24: =$D24&"" | C24: =IF($D24="","",基本情報入力!$F15) | Y24: =IF($X24="","","通")
B25: =$D25&"" | C25: =IF($D25="","",基本情報入力!$F16) | Y25: =IF($X25="","","通")
B26: =$D26&"" -> 返信用封筒(書類の返送にご使用ください) | C26: =IF($D26="","",基本情報入力!$F17) -> ⑼ | D26: =IF(基本情報入力!$G17="","",基本情報入力!$G17) -> 返信用封筒(書類の返送にご使用ください) | Y26: =IF($X26="","","通")
B27: =$D27&"" | C27: =IF($D27="","",基本情報入力!$F18) | D27: =IF(基本情報入力!$G18="","",基本情報入力!$G18) | Y27: =IF($X27="","","通")
B28: =$D28&"" | C28: =IF($D28="","",基本情報入力!$F19) | D28: =IF(基本情報入力!$G19="","",基本情報入力!$G19) | Y28: =IF($X28="","","通")
C29: 通信欄：
C30: 平素より大変お世話になっております。 法定相続情報一覧図をお送り致します。こちらは戸籍に代わり、相続関係をしめす公的な証明書となります。ご活用いただければ幸いです。 ご不明点等ございましたらお気軽にご連絡ください。 業務完了まで、何卒よろしくお願い致します。
