Workbook
Name 業務リスト: #REF!
Name 業務リスト: #REF!
Name 業務リスト: #REF!
Name 新宿: #REF!
Name 新宿: #REF!
Name 新宿: #REF!
Name 相続人リスト: #REF!,#REF!,#REF!,#REF!,#REF!,#REF!
Name 相続人リスト: #REF!,#REF!,#REF!,#REF!,#REF!,#REF!
Name 相続人リスト: #REF!,#REF!,#REF!,#REF!,#REF!,#REF!
Name 続柄リスト: #REF!
Name 続柄リスト: #REF!
Name 続柄リスト: #REF!
Name 大坂: #REF!
Name 大坂: #REF!
Name 大坂: #REF!
Name 担当: 基本画面!$J$42:$K$141
Name 担当者リスト: #REF!
Name 担当者リスト: #REF!
Name 担当者リスト: #REF!
Name 担当者リスト: #REF!
Name 担当者情報: #REF!
Name 担当者情報: #REF!
Name 担当者情報: #REF!
Name 本店: #REF!
Name 本店: #REF!
Name 本店: #REF!

Sheet 基本画面
A1: 基本情報入力
A2: ・こちらの『基本情報入力』シートの【⒈基本情報】~【⒋被相続人・相続人 基本情報】に必要事項を入力ください
A3: ・ヒアリングシートを参考に【⒍金融機関 基本情報】と【⒎不動産 基本情報】に必要事項を入力ください
A4: ・戸籍担当へ戸籍収集等を依頼される場合、『戸籍収集引継書』の14行より下、指示部分は直接入力ください
A5: ・『送付状』『返送書類リスト』は印刷後、分けずにホチキス止めして、まとめて送付ください
A8: ⒈基本情報 | B8: ※黄色セルは必ず入力ください | F8: ⒉送付書類 | H8: 返送書類リスト記載チェック | J8: ⒊返送書類
A9: 顧客コード | C9: 登記担当 | F9: ⑴ | G9: 契約書 | I9: FALSE
A10: 顧客名 | C10: 税チェ関与 | F10: ⑵ | G10: 重要事項説明書 | I10: FALSE
A11: プラン | B11: 遺言作成サポート | C11: 値引きの有無 | F11: ⑶ | G11: 相続手続き業務に関する確認事項 | I11: FALSE
A12: 拠点 | B12: 東京 | C12: 委任状の日付 | F12: ⑷ | G12: 委任状 | I12: FALSE
A13: 担当① | C13: 担当② | F13: ⑸ | G13: 口座の凍結についての確認書 | I13: FALSE
A14: 初回送付日 | F14: ⑹ | G14: 不動産・金融機関情報一覧 | I14: FALSE
A15: 送付先1 | F15: ⑺ | G15: 戸籍関係情報 | I15: FALSE
A16: 送付先2 | F16: ⑻ | G16: 請求書 | I16: FALSE
A17: 委任状通数 | F17: ⑼ | G17: 返信用封筒(書類の返送にご使用ください) | I17: FALSE
A18: 印鑑証明書数 | F18: ⑽ | I18: FALSE
A19: 返信用封筒通数 | F19: ⑾ | I19: FALSE
A21: ⒋遺言者・相続人 基本情報
A22: 番号 | B22: 続柄 | C22: 氏名 (行政 太郎) | D22: ふりがな (ぎょうせい たろう) | E22: 生年月日 (R1.1.1) | F22: 死亡日 (R1.1.1) | G22: 〒 (000-0000) | H22: 住所1 (東京都中央区八重洲一丁目7-20) | I22: 住所2 (八重洲口会館2階) | J22: TEL (00-0000-0000) | K22: 本籍地 (東京都中央区八重洲一丁目7番20号) | L22: 筆頭者 (行政 太郎) | Q22: =IF(R22="",FALSE,TRUE) -> FALSE | R22: =J9&""
A23: 遺言者（委任者） | B23: 本人 | Q23: =IF(R23="",FALSE,TRUE) -> FALSE | R23: =J10&""
A24: 相続人① | Q24: =IF(R24="",FALSE,TRUE) -> FALSE | R24: =J11&""
A25: 相続人② | Q25: =IF(R25="",FALSE,TRUE) -> FALSE | R25: =J12&""
A26: 相続人③ | Q26: =IF(R26="",FALSE,TRUE) -> FALSE | R26: =J13&""
A27: 相続人④
A28: 相続人⑤
A29: 相続人⑥
A30: 相続人⑦
A31: 相続人⑧
A32: 相続人⑨
A33: 相続人⑩
A34: 相続人⑪
A35: 相続人⑫
A37: ⒌戸籍担当
A38: 法定相続情報 | D38: 戸籍
A39: 配偶者 | D39: 対象者
A40: 相続人
A41: 相続人 | D41: 戸籍担当者
A42: 相続人 | D42: 拠点 | E42: 担当者
A43: 相続人 | D43: 東京 | E43: 増田
A46: ⒍金融機関 基本情報 | G46: ⒎不動産 基本情報
...

Sheet 戸籍収集引継書 
A1: =基本画面!$C$23 -> 0 | D1: =基本画面!$B$9 -> 0 | F1: =基本画面!$B$11 -> 遺言作成サポート | H1: =基本画面!$D$13 -> 0
A3: ふりがな | B3: =基本画面!$D$23&""
A4: 氏名 | B4: =基本画面!$C$23&""
A5: 最新の住所 | B5: =基本画面!$H$23&" "&基本画面!$I$23
A6: 生年月日 | B6: =IF(基本画面!$E$23="","",基本画面!$E$23)
A7: 本籍 | B7: =基本画面!$K$23&""
A8: 筆頭者 | B8: =基本画面!$L$23&""
A9: 委任者 | B9: =基本画面!$D$23&""
A10: 本人 | B10: =基本画面!$C$23&"" | C10: =基本画面!$H$23&" "&基本画面!$I$23
A11: 取得書類
A13: □申請中 □完了 | B13: 遺言者の現在戸籍及び推定相続人の現在戸籍の取得をお願いします。
A14: □申請中 □完了 | B14: R7年度名寄帳の取得もお願いします。（千代田区、横浜市西区、鎌倉市）
A15: □申請中 □完了
A16: □申請中 □完了
A17: □申請中 □完了
A18: 備考
B19: 推定相続人は妻、子供（３名）の計4名
A21: 引継ぎ前のチェックリスト
A22: 確認済 | B22: 予備的遺言等含め必要な戸籍類を確認した。
A23: 確認済 | B23: 遺言に記載する不動産について名寄帳の取得が必要か確認した。
A24: 確認済

Sheet 戸籍申請書
A1: 戸籍・住民票等交付申請書
A3: =TODAY() -> 45978
A4: 本籍 | E4: =基本画面!K23&""
A5: 筆頭者 | E5: =基本画面!L23&""
A6: 住所 | E6: =基本画面!H23&""&基本画面!I23
A7: 登記簿上の住所
A8: 登記簿上の氏名
A9: 種類 | F9: 戸籍謄本 | J9: 除籍謄本・改製原戸籍 | R9: 廃棄証明書（戸籍） | W9: 各 1 通
F10: 戸籍の附票謄本（本籍・筆頭者の記載必要） | R10: 廃棄証明書（附票）
F11: 不在籍・不在住証明書 | O11: 住居表示実施証明書
F12: 住民票（本籍・筆頭者・世帯主・続柄の記載必要）
F13: 住民票除票（本籍・筆頭者・世帯主・続柄の記載必要）
A14: 必要なもの | F14: =CONCATENATE("遺言者「",I32,"」の世帯全部の住民票") -> 遺言者「0」の世帯全部の住民票
F15: =CONCATENATE("遺言者「",I32,"」の出生から現在までの戸籍謄本") -> 遺言者「0」の出生から現在までの戸籍謄本
F16: =CONCATENATE("遺言者「",I32,"」の現在戸籍謄本") -> 遺言者「0」の現在戸籍謄本
F17: 「遺言者の亡き両親及び亡き兄弟姉妹」の出生～死亡までの戸籍謄本
F18: 「」の現在戸籍謄本
A25: 備考 | E25: 該当がない場合、申請内容に不明な点がある場合はお手数ですがご連絡ください。
E26: 重複するものは１通のみお送りいただければ結構です。
E27: 焼失、廃棄等の場合は、その旨の証明書をお送りください。
E28: 氏名不明の方につきまして申請内容の範囲内であれば可能な限り交付願います。
E29: 謄本の交付ができない場合には抄本の交付をお願いします。
E30: 附票及び住民票は戸籍との同一性を担保するため、本籍及び筆頭者の記載をお願い致します。
E31: 遺言者 | I31: =IF(基本画面!D23=0,"",基本画面!D23) | R31: 生年月日 | V31: 死亡日
I32: =基本画面!C23 -> 0 | R32: =IF(基本画面!E23=0,"",基本画面!E23) | V32: =IF(基本画面!F23=0,"",基本画面!F23)
A33: 使いみち 提出先 | F33: 推定相続人の調査のため
F34: 遺言公正証書作成のため公証役場へ提出
A37: 委任者 | B37: 住所 | E37: =基本画面!H23&" "&基本画面!I23
B38: 氏名 | E38: =IF(基本画面!D23=0,"",基本画面!D23) | R38: 生年月日 | V38: 遺言者
E39: =IF(基本画面!C23=0,"",基本画面!C23) | R39: =IF(基本画面!E23=0,"",基本画面!E23) | V39: 本人
A40: 申請者 | B40: 事務所 | E40: 東京都中央区八重洲一丁目7-20 | V40: 遺言者との関係
V41: 代理人
B42: ぎょうせいしょしほうじんちぇすたーだいひょうしゃいんこしみずせんさく | V42: 連絡先
B43: 行政書士法人チェスター 代表社員 清水 茜作 （法人登録番号 東京 第1303101号） | V43: =VLOOKUP(V44,基本画面!$G$72:$H$150,2,FALSE) -> 050-6861-5751
V44: =基本画面!E43 -> 増田
A45: 営業時間：午前9時～午後5時（平日のみ）※11:45～12:45は昼休みのため業務を休止しています | V45: 案件番号
A46: =IFERROR("従たる事務所（返送先）："&VLOOKUP(基本画面!$D$43,基本画面!$N$73:$T$140,3,FALSE),"") | V46: =基本画面!B9 -> 0

Sheet 戸籍申請書（相）
A1: 戸籍・住民票等交付申請書
A3: =TODAY() -> 45978
A4: 本籍 | E4: =IFERROR(VLOOKUP(基本画面!$E$39,基本画面!$C$23:$K$35,9,FALSE),"")&""
A5: 筆頭者 | E5: =IFERROR(VLOOKUP(基本画面!$E$39,基本画面!$C$23:$L$35,10,FALSE),"")&""
A6: 住所 | E6: =IFERROR(VLOOKUP(基本画面!$E$39,基本画面!$C$23:$K$35,6,FALSE),"")&""
A7: 方書 | E7: =IFERROR(VLOOKUP(基本画面!$E$39,基本画面!$C$23:$K$35,7,FALSE),"")&""
A8: 種類 | F8: 戸籍謄本 | J8: 除籍謄本・改製原戸籍 | R8: 廃棄証明書（戸籍） | W8: 各 1 通
F9: 戸籍の附票謄本（本籍・筆頭者の記載必要） | R9: 廃棄証明書（附票）
F10: 不在籍・不在住証明書 | O10: 住居表示実施証明書
F11: 住民票（本籍・筆頭者・世帯主・続柄の記載必要）
F12: 住民票除票（本籍・筆頭者・世帯主・続柄の記載必要）
A13: 必要なもの | F13: =基本画面!E39 -> 0
F14: =F13 -> 0
F15: =CONCATENATE("「",F13,"」が死亡している場合") -> 「0」が死亡している場合
F16: =CONCATENATE("「",F13,"」の出生～死亡までの戸籍謄本") -> 「0」の出生～死亡までの戸籍謄本
F17: =CONCATENATE("「",F13,"の子供」の現在戸籍（転籍等で現在のが発行できない場合は除籍謄本）") -> 「0の子供」の現在戸籍（転籍等で現在のが発行できない場合は除籍謄本）
F18: =CONCATENATE("「",F13,"の子供」の戸籍附票（転籍等で現在のものが発行できない場合は不要）") -> 「0の子供」の戸籍附票（転籍等で現在のものが発行できない場合は不要）
F19: =CONCATENATE("「",F13,"」の婚姻～死亡までの戸籍謄本") -> 「0」の婚姻～死亡までの戸籍謄本
A23: 備考 | E23: 該当がない場合、申請内容に不明な点がある場合はお手数ですがご連絡ください。
E24: 重複するものは１通のみお送りいただければ結構です。
E25: 焼失、廃棄等の場合は、その旨の証明書をお送りください。
E26: 氏名不明の方につきまして申請内容の範囲内であれば可能な限り交付願います。
E27: 謄本の交付ができない場合には抄本の交付をお願いします。
E28: 附票及び住民票は戸籍との同一性を担保するため、本籍及び筆頭者の記載をお願い致します。
E29: 遺言者 | I29: =IF(基本画面!D23=0,"",基本画面!D23) | R29: 生年月日 | V29: 死亡日
I30: =基本画面!C23 -> 0 | R30: =IF(基本画面!E23=0,"",基本画面!E23) | V30: =IF(基本画面!F23=0,"",基本画面!F23)
A31: 使いみち 提出先 | F31: 推定相続人の調査のため
F32: 遺言公正証書作成のため公証役場へ提出
A35: 委任者 | B35: 住所 | E35: =基本画面!H23&" "&基本画面!I23
B36: 氏名 | E36: =IF(基本画面!D23=0,"",基本画面!D23) | R36: 生年月日 | V36: 遺言者との続柄
E37: =IF(基本画面!C23=0,"",基本画面!C23) | R37: =IF(基本画面!E23=0,"",基本画面!E23) | V37: 本人
A38: 申請者 | B38: 事務所 | E38: 東京都中央区八重洲一丁目7-20 | V38: 遺言者との関係
V39: 代理人
B40: ぎょうせいしょしほうじんちぇすたーだいひょうしゃいんしみずせんさく | V40: 連絡先
B41: 行政書士法人チェスター 代表社員 清水 茜作 （法人登録番号 東京 第1303101号） | V41: =VLOOKUP(V42,基本画面!$G$72:$H$150,2,FALSE) -> 050-6861-5751
V42: =基本画面!E43 -> 増田
A43: 営業時間：午前9時～午後5時（平日のみ）※11:45～12:45は昼休みのため業務を休止しています | V43: 案件番号
A44: =IFERROR("従たる事務所（返送先）："&VLOOKUP(基本画面!$D$43,基本画面!$N$73:$T$150,3,FALSE),"") | V44: =基本画面!B9 -> 0

Sheet 名寄帳申請書
A1: 名寄帳・評価証明書等交付申請書
A3: =TODAY() -> 45978
A4: 所有者 | E4: =基本画面!H23&" "&基本画面!I23
E5: =I35 -> 0
A6: 必要なもの | F6: 令和5年度 名寄帳（共有物件、非課税物件等含む全て） | W6: 各 1 通
F7: 令和6年度 名寄帳（共有物件、非課税物件等含む全て）
F8: 令和7年度 名寄帳（共有物件、非課税物件等含む全て）
F9: 上記所有者の下記物件につき、最新年度評価証明書をお送りください。
E10: 物件
E11: 種類 | K11: 所在 | U11: 家屋番号
F12: 土地 | I12: 家屋
F13: 土地 | I13: 家屋
F14: 土地 | I14: 家屋
F15: 土地 | I15: 家屋
A16: 参考資料
B17: 登記情報 | F17: 全部事項証明書 | L17: 名寄帳 | P17: 評価証明書 | U17: 課税明細書
A18: 証明が必要な内容
B19: 物件の評価額及び家屋番号の記載
B20: ※評価額が0円（非課税）の場合、近傍宅地（又は類似地目）1㎡当たりの価格の記載
B21: ※共有物件の場合、持分割合及び持分の評価額の記載
B22: 物件の一部又は全部が公衆用道路又は悪用道路により非課税の場合、
B23: 非課税部分の面積及び非課税条文の記載
B24: ※（例）非課税地積・〇〇㎡、非課税条文・法348条2項5項・公衆用道路
A25: 備考 | E25: 名寄帳に評価額（近傍宅地）や非課税条文等が記載できない場合、
E26: 追加で最新年度の評価証明書を発行してください。
E27: 所有の建物に敷地権が設定されている場合は土地の名寄帳も発行してください。
E28: 証明内容は全て、印字又は消せないペンで記入してください。（付箋不可）
E29: 特記事項を記載できる書類がない場合は付箋等でその旨をお知らせください。
E30: 名寄帳・評価証明書等の取り扱いがない場合、
E31: 代わりの書類（非課税証明書・公課証明書等）の発行をお願い致します。
E32: 該当がない場合、申請内容に不明な点がある場合はお手数ですがご連絡ください。
E34: 遺言者 | I34: =IF(基本画面!D23=0,"",基本画面!D23) | R34: 生年月日 | V34: 死亡日
I35: =基本画面!C23 -> 0 | R35: =IF(基本画面!E23=0,"",基本画面!E23) | V35: =IF(基本画面!F23=0,"",基本画面!F23)
A36: 使いみち 提出先 | F36: 財産の調査のため
F37: 遺言公正証書作成のため公証役場へ提出
A39: 委任者 | B39: 住所 | E39: =基本画面!H23&" "&基本画面!I23
B40: 氏名 | E40: =IF(基本画面!D23=0,"",基本画面!D23) | R40: 生年月日 | V40: 遺言者との続柄
E41: =IF(基本画面!C23=0,"",基本画面!C23) | R41: =IF(基本画面!E23=0,"",基本画面!E23) | V41: 本人
A42: 申請者 | B42: 事務所 | E42: 東京都中央区八重洲一丁目7-20 | V42: 遺言者との関係
V43: 代理人
...

Sheet 実費台紙
A1: レタパシール 貼付台紙 | I1: キントーン№ | N1: 顧客名 | W1: 遺言者 | AG1: 案件 | AM1: 担当
I2: =基本画面!B9 -> 0 | N2: =基本画面!C23 -> 0 | W2: =基本画面!C23 -> 0 | AG2: =基本画面!B11 -> 遺言作成サポート | AM2: =基本画面!B13&"・"&基本画面!D13 -> ・
A5: 送付 | V5: 返送
